<?xml version="1.0"?>
<robot name="simple_green_crane">

<material name="green">
    <color rgba="0 0.8 0 1"/>
  </material>

  <link name="base_link">
    <visual>
      <geometry>
        <mesh filename="package://urdf_tutorial/meshes/frame_URDF.STL"/>
      </geometry>
      <origin rpy="0.0 0 0" xyz="0 0 0.57207"/>
      <material name="green"/>
    </visual>
  </link>

  <link name="crane_boom">
    <visual>
    <origin rpy="0 0 0" xyz="3.10836 0 0.06343"/>
      <geometry>
        <mesh filename="package://urdf_tutorial/meshes/boom_URDF.STL"/>
      </geometry>
      <material name="green"/>
    </visual>
  </link>

  <joint name="base_to_crane_boom" type="revolute">
  <axis xyz="0 1 0"/>
  <limit effort="1000.0" lower="0.3267" upper="-0.6948" velocity="0.5"/>
    <parent link="base_link"/>
    <child link="crane_boom"/>
    <origin rpy="0 0 0" xyz="-0.56876 0 1.752"/>
  </joint>


  <link name="tool_tip">
    <visual>
      <geometry>
        <box size="0.1 0.1 0.1"/>
      </geometry>
      <origin rpy = "0 0 0" xyz="0 0 0"/>
      <material name="green"/>
    </visual>
  </link>
  
  <joint name="crane_boom_to_tooltip" type="fixed">
    <origin rpy="0 0 0"  xyz="3.6 0 0"/>
    <parent link="crane_boom"/>
    <child link="tool_tip"/>
  </joint>
  

</robot>
